Traceback (most recent call last):
  File "/opt/hostedtoolcache/Python/3.7.13/x64/lib/python3.7/site-packages/jupyter_cache/executors/utils.py", line 56, in single_nb_execution
    record_timing=False,
  File "/opt/hostedtoolcache/Python/3.7.13/x64/lib/python3.7/site-packages/nbclient/client.py", line 1204, in execute
    return NotebookClient(nb=nb, resources=resources, km=km, **kwargs).execute()
  File "/opt/hostedtoolcache/Python/3.7.13/x64/lib/python3.7/site-packages/nbclient/util.py", line 84, in wrapped
    return just_run(coro(*args, **kwargs))
  File "/opt/hostedtoolcache/Python/3.7.13/x64/lib/python3.7/site-packages/nbclient/util.py", line 62, in just_run
    return loop.run_until_complete(coro)
  File "/opt/hostedtoolcache/Python/3.7.13/x64/lib/python3.7/asyncio/base_events.py", line 587, in run_until_complete
    return future.result()
  File "/opt/hostedtoolcache/Python/3.7.13/x64/lib/python3.7/site-packages/nbclient/client.py", line 664, in async_execute
    cell, index, execution_count=self.code_cells_executed + 1
  File "/opt/hostedtoolcache/Python/3.7.13/x64/lib/python3.7/site-packages/nbclient/client.py", line 965, in async_execute_cell
    await self._check_raise_for_error(cell, cell_index, exec_reply)
  File "/opt/hostedtoolcache/Python/3.7.13/x64/lib/python3.7/site-packages/nbclient/client.py", line 862, in _check_raise_for_error
    raise CellExecutionError.from_cell_and_msg(cell, exec_reply_content)
nbclient.exceptions.CellExecutionError: An error occurred while executing the following cell:
------------------
from GraphDataset import GraphDataset

if local:
    file_names = [
        "/teams/DSC180A_FA20_A00/b06particlephysics/train/ntuple_merged_10.root"
    ]
    file_names_test = [
        "/teams/DSC180A_FA20_A00/b06particlephysics/test/ntuple_merged_0.root"
    ]
else:
    file_names = [
        "root://eospublic.cern.ch//eos/opendata/cms/datascience/HiggsToBBNtupleProducerTool/HiggsToBBNTuple_HiggsToBB_QCD_RunII_13TeV_MC/train/ntuple_merged_10.root"
    ]
    file_names_test = [
        "root://eospublic.cern.ch//eos/opendata/cms/datascience/HiggsToBBNtupleProducerTool/HiggsToBBNTuple_HiggsToBB_QCD_RunII_13TeV_MC/test/ntuple_merged_0.root"
    ]

graph_dataset = GraphDataset(
    "gdata_train",
    features,
    labels,
    spectators,
    n_events=8000,
    n_events_merge=1,
    file_names=file_names,
)

test_dataset = GraphDataset(
    "gdata_test",
    features,
    labels,
    spectators,
    n_events=2000,
    n_events_merge=1,
    file_names=file_names_test,
)
------------------

[0;31m---------------------------------------------------------------------------[0m
[0;31mTypeError[0m                                 Traceback (most recent call last)
[0;32m/tmp/ipykernel_4884/3344982825.py[0m in [0;36m<module>[0;34m[0m
[1;32m     23[0m     [0mn_events[0m[0;34m=[0m[0;36m8000[0m[0;34m,[0m[0;34m[0m[0;34m[0m[0m
[1;32m     24[0m     [0mn_events_merge[0m[0;34m=[0m[0;36m1[0m[0;34m,[0m[0;34m[0m[0;34m[0m[0m
[0;32m---> 25[0;31m     [0mfile_names[0m[0;34m=[0m[0mfile_names[0m[0;34m,[0m[0;34m[0m[0;34m[0m[0m
[0m[1;32m     26[0m )
[1;32m     27[0m [0;34m[0m[0m

[0;31mTypeError[0m: __init__() got an unexpected keyword argument 'n_events'
TypeError: __init__() got an unexpected keyword argument 'n_events'

